Exception in thread Thread-3:
Traceback (most recent call last):
  File "C:\Users\GMU Observtory1\anaconda3\lib\threading.py", line 926, in _bootstrap_inner
    self.run()
  File "C:\Users\GMU Observtory1\-omegalambda\main\controller\dome.py", line 26, in run
    self.Dome = win32com.client.Dispatch(pythoncom.CoGetInterfaceAndReleaseStream(self.marhsalled_dome, pythoncom.IID_IDispatch))
AttributeError: 'Dome' object has no attribute 'marhsalled_dome'

(Thread-2  ) Telescope thread is alive
(Thread-1  ) Camera thread is alive
The program is ready to start taking images of TestTOI1234.01.  Please take this time to focus and check the pointing of the target.  When you are ready, press Enter: Telescope is unparked; tracking at sidereal rate
(Thread-2  ) Telescope thread is alive
Exception in thread Thread-2:
Traceback (most recent call last):
  File "C:\Users\GMU Observtory1\anaconda3\lib\site-packages\astropy\units\format\generic.py", line 566, in _do_parse
    return cls._parse_unit(s, detailed_exception=False)
  File "C:\Users\GMU Observtory1\anaconda3\lib\site-packages\astropy\units\format\generic.py", line 487, in _parse_unit
    raise ValueError()
ValueError

During handling of the above exception, another exception occurred:

Traceback (most recent call last):
  File "C:\Users\GMU Observtory1\anaconda3\lib\site-packages\astropy\units\core.py", line 1854, in __call__
    return f.parse(s)
  File "C:\Users\GMU Observtory1\anaconda3\lib\site-packages\astropy\units\format\generic.py", line 551, in parse
    result = cls._do_parse(s, debug=debug)
  File "C:\Users\GMU Observtory1\anaconda3\lib\site-packages\astropy\units\format\generic.py", line 569, in _do_parse
    return cls._parser.parse(s, lexer=cls._lexer, debug=debug)
  File "C:\Users\GMU Observtory1\anaconda3\lib\site-packages\astropy\extern\ply\yacc.py", line 331, in parse
    return self.parseopt_notrack(input, lexer, debug, tracking, tokenfunc)
  File "C:\Users\GMU Observtory1\anaconda3\lib\site-packages\astropy\extern\ply\yacc.py", line 1061, in parseopt_notrack
    lookahead = get_token()     # Get the next token
  File "C:\Users\GMU Observtory1\anaconda3\lib\site-packages\astropy\extern\ply\lex.py", line 386, in token
    newtok = self.lexerrorf(tok)
  File "C:\Users\GMU Observtory1\anaconda3\lib\site-packages\astropy\units\format\generic.py", line 173, in t_error
    f"Invalid character at col {t.lexpos}")
ValueError: Invalid character at col 2

During handling of the above exception, another exception occurred:

Traceback (most recent call last):
  File "C:\Users\GMU Observtory1\anaconda3\lib\threading.py", line 926, in _bootstrap_inner
    self.run()
  File "C:\Users\GMU Observtory1\-omegalambda\main\controller\telescope.py", line 36, in run
    function(*args, **kwargs)
  File "C:\Users\GMU Observtory1\-omegalambda\main\controller\telescope.py", line 94, in Slew
    (ra, dec) = conversion_utils.convert_J2000_to_apparent(ra, dec)
  File "C:\Users\GMU Observtory1\-omegalambda\main\common\util\conversion_utils.py", line 61, in convert_J2000_to_apparent
    coords_J2000 = SkyCoord(ra = ra*u.hourangle, dec = dec*u.degree, frame = 'icrs') #ICRS Equinox is always J2000
  File "C:\Users\GMU Observtory1\anaconda3\lib\site-packages\astropy\units\core.py", line 703, in __rmul__
    return Unit(m) * self
  File "C:\Users\GMU Observtory1\anaconda3\lib\site-packages\astropy\units\core.py", line 1874, in __call__
    raise ValueError(msg)
ValueError: '00:13:14.1528' did not parse as unit: Invalid character at col 2 If this is meant to be a custom unit, define it with 'u.def_unit'. To have it recognized inside a file reader or other code, enable it with 'u.add_enabled_units'. For details, see http://docs.astropy.org/en/latest/units/combining_and_defining.html


Traceback (most recent call last):
  File "C:\Users\GMU Observtory1\anaconda3\lib\runpy.py", line 193, in _run_module_as_main
    "__main__", mod_spec)
  File "C:\Users\GMU Observtory1\anaconda3\lib\runpy.py", line 85, in _run_code
    exec(code, run_globals)
  File "C:\Users\GMU Observtory1\-omegalambda\main\drivers\driver.py", line 32, in <module>
    run_object.observe()
  File "C:\Users\GMU Observtory1\-omegalambda\main\observing\observation_run.py", line 40, in observe
    while (self.telescope.Telescope.Slewing or self.dome.Dome.Slewing):
  File "C:\Users\GMU Observtory1\anaconda3\lib\site-packages\win32com\client\dynamic.py", line 516, in __getattr__
    ret = self._oleobj_.Invoke(retEntry.dispid,0,invoke_type,1)
pywintypes.com_error: (-2147417842, 'The application called an interface that was marshalled for a different thread.', None, None)

